2022-12-24 00:31:25,009 menu.expense ERROR    Message can't be deleted for everyone
Traceback (most recent call last):
  File "/Users/ealmina/Documents/money_tracker/src/decorators.py", line 21, in wrapper
    await context.bot.delete_message(
  File "/Users/ealmina/Documents/money_tracker/venv/lib/python3.10/site-packages/telegram/ext/_extbot.py", line 1077, in delete_message
    return await super().delete_message(
  File "/Users/ealmina/Documents/money_tracker/venv/lib/python3.10/site-packages/telegram/_bot.py", line 242, in decorator
    result = await func(*args, **kwargs)
  File "/Users/ealmina/Documents/money_tracker/venv/lib/python3.10/site-packages/telegram/_bot.py", line 736, in delete_message
    result = await self._post(
  File "/Users/ealmina/Documents/money_tracker/venv/lib/python3.10/site-packages/telegram/_bot.py", line 303, in _post
    return await self._do_post(
  File "/Users/ealmina/Documents/money_tracker/venv/lib/python3.10/site-packages/telegram/ext/_extbot.py", line 281, in _do_post
    return await super()._do_post(
  File "/Users/ealmina/Documents/money_tracker/venv/lib/python3.10/site-packages/telegram/_bot.py", line 334, in _do_post
    return await request.post(
  File "/Users/ealmina/Documents/money_tracker/venv/lib/python3.10/site-packages/telegram/request/_baserequest.py", line 162, in post
    result = await self._request_wrapper(
  File "/Users/ealmina/Documents/money_tracker/venv/lib/python3.10/site-packages/telegram/request/_baserequest.py", line 325, in _request_wrapper
    raise BadRequest(message)
telegram.error.BadRequest: Message can't be deleted for everyone
2022-12-24 00:31:30,266 menu.expense INFO     calling function insert_expense with args text = 1 and callback data =  and user_data msg:3323;category:2
